Workbook

Sheet Full Inventory Cost
A1: Items | B1: % increase '23 -'24 | C1: % increase '24 -'25 | D1: OLD 2023 Price | E1: OLD 2024 Price | F1: Midyear 2024 Price | G1: Current Price | H1: Store | I1: Quantity | J1: Quantity in oz | K1: Per oz or unit price | L1: Price per cup | M1: Price per tbsp. | N1: Price per Tsp. | O1: Price Per Gram | P1: 1 oz = 2 tbsp. | Q1: 1 oz = 6 tsp. | R1: 1 oz = .125 cups
A2: -------------------
A3: Drink Supplies
A4: Espresso Beans ($9 + tarriff of 10%) | B4: =((E4-D4)/D4) -> 0 | C4: =((G4-F4)/F4) -> 0.16470588 | D4: 8.5 | E4: 8.5 | F4: 8.5 | G4: 9.9 | H4: Numinous | I4: 1lb | J4: 16 | K4: =G4/J4 -> 0.61875 | L4: =K4*8 -> 4.95 | M4: =L4/16 -> 0.309375 | N4: =M4/3 -> 0.103125 | O4: =K4/28.3495 -> 0.021825782
A5: House Beans | B5: =((E5-D5)/D5) -> 0 | C5: =((G5-F5)/F5) -> 0.16470588 | D5: 8.5 | E5: 8.5 | F5: 8.5 | G5: 9.9 | H5: Numinous | I5: 1lb | J5: 16 | K5: =G5/J5 -> 0.61875 | L5: =K5*8 -> 4.95 | M5: =L5/16 -> 0.309375 | N5: =M5/3 -> 0.103125 | O5: =K5/28.3495 -> 0.021825782
A6: Decaf Beans | B6: =((E6-D6)/D6) -> 0 | C6: =((G6-F6)/F6) -> 0.16470588 | D6: 8.5 | E6: 8.5 | F6: 8.5 | G6: 9.9 | H6: Numinous | I6: 1lb | J6: 16 | K6: =G6/J6 -> 0.61875 | L6: =K6*8 -> 4.95 | M6: =L6/16 -> 0.309375 | N6: =M6/3 -> 0.103125 | O6: =K6/28.3495 -> 0.021825782
A7: Rishi Masala Chai (32 oz) | B7: =((E7-D7)/D7) -> 0 | C7: =((G7-F7)/F7) -> 0 | D7: 70 | E7: 70 | F7: 70 | G7: 70 | H7: Numinous | I7: 12 quarts | J7: 384 | K7: =G7/J7 -> 0.18229167 | L7: =K7*8 -> 1.4583333 | M7: =L7/16 -> 0.091145833 | N7: =M7/3 -> 0.030381944 | O7: =K7/28.3495 -> 0.0064301546
A8: HEB Creamy Creations Vanilla Ice Cream | B8: =((E8-D8)/D8) -> 0.040114613 | C8: =((G8-F8)/F8) -> -0.084022039 | D8: 6.98 | E8: 7.26 | F8: 7.26 | G8: 6.65 | H8: HEB | I8: 64oz | J8: 64 | K8: =G8/J8 -> 0.10390625 | L8: =K8*8 -> 0.83125 | M8: =L8/16 -> 0.051953125 | N8: =M8/3 -> 0.017317708 | O8: =K8/28.3495 -> 0.0036651881
A9: HEB Whole Frozen Strawberries (5 lbs) | B9: =((E9-D9)/D9) -> 0 | C9: =((G9-F9)/F9) -> 0.057803468 | D9: 10.38 | E9: 10.38 | F9: 10.38 | G9: 10.98 | H9: HEB | I9: 5lb bag | J9: 80 | K9: =G9/J9 -> 0.13725 | L9: =K9*8 -> 1.098 | M9: =L9/16 -> 0.068625 | N9: =M9/3 -> 0.022875 | O9: =K9/28.3495 -> 0.0048413552
A10: HEB Whole Frozen Blueberries (5 lbs) | B10: =((E10-D10)/D10) -> 0 | C10: =((G10-F10)/F10) -> -0.20451527 | D10: 15.06 | E10: 15.06 | F10: 15.06 | G10: 11.98 | H10: HEB | I10: 5lb bag | J10: 80 | K10: =G10/J10 -> 0.14975 | L10: =K10*8 -> 1.198 | M10: =L10/16 -> 0.074875 | N10: =M10/3 -> 0.024958333 | O10: =K10/28.3495 -> 0.0052822801
A11: HEB Frozen Mango Chunks (16 oz) | B11: =((E11-D11)/D11) -> 0.026490066 | C11: =((G11-F11)/F11) -> 0.051612903 | D11: 3.02 | E11: 3.1 | F11: 3.1 | G11: 3.26 | H11: HEB | I11: 16oz | J11: 16 | K11: =G11/J11 -> 0.20375 | L11: =K11*8 -> 1.63 | M11: =L11/16 -> 0.101875 | N11: =M11/3 -> 0.033958333 | O11: =K11/28.3495 -> 0.0071870756
A12: HEB More Fruit Peach & Mango Fruit Spread (15.5oz) | B12: =((E12-D12)/D12) -> 0.1570997 | C12: =((G12-F12)/F12) -> 0.01305483 | D12: 3.31 | E12: 3.83 | F12: 3.83 | G12: 3.88 | H12: HEB | I12: 15.5oz | J12: 15.5 | K12: =G12/J12 -> 0.25032258 | L12: =K12*8 -> 2.0025806 | M12: =L12/16 -> 0.12516129 | N12: =M12/3 -> 0.04172043 | O12: =K12/28.3495 -> 0.0088298764
A13: Hill Country Fare Pineapple Preserves (16 oz) | B13: =((E13-D13)/D13) -> 0.11178248 | D13: 3.31 | E13: 3.68 | F13: 2.96 | G13: 3.17 | H13: HEB | I13: 16oz | J13: 15.5 | K13: =G13/J13 -> 0.20451613 | L13: =K13*8 -> 1.636129 | M13: =L13/16 -> 0.10225806 | N13: =M13/3 -> 0.034086022 | O13: =K13/28.3495 -> 0.0072141
A14: Hill Country Fare Strawberry Preserves (32 oz) | B14: =((E14-D14)/D14) -> -0.014851485 | C14: =((G14-F14)/F14) -> 0.065326633 | D14: 4.04 | E14: 3.98 | F14: 3.98 | G14: 4.24 | H14: HEB | I14: 32oz | J14: 32 | K14: =G14/J14 -> 0.1325 | L14: =K14*8 -> 1.06 | M14: =L14/16 -> 0.06625 | N14: =M14/3 -> 0.022083333 | O14: =K14/28.3495 -> 0.0046738038
A15: Fresh Granny Smith Apples (3 lb Bag) | B15: =((E15-D15)/D15) -> 0.048309179 | C15: =((G15-F15)/F15) -> -0.039170507 | D15: 4.14 | E15: 4.34 | F15: 4.34 | G15: 4.17 | H15: HEB | I15: 3lb bag | J15: 48 | K15: =G15/J15 -> 0.086875 | L15: =K15*8 -> 0.695 | M15: =L15/16 -> 0.0434375 | N15: =M15/3 -> 0.014479167 | O15: =K15/28.3495 -> 0.0030644279
A16: HEB Fresh Bananas | B16: =((E16-D16)/D16) -> -0.14965986 | C16: =((G16-F16)/F16) -> 0.04 | D16: 1.47 | E16: 1.25 | F16: 1.25 | G16: 1.3 | H16: HEB | I16: 2.58lbs | J16: 41.28 | K16: =G16/J16 -> 0.031492248 | L16: =K16*8 -> 0.25193798 | M16: =L16/16 -> 0.015746124 | N16: =M16/3 -> 0.005248708 | O16: =K16/28.3495 -> 0.0011108573
A17: HEB Spinach (9oz Bag) | B17: =((E17-D17)/D17) -> 0 | C17: =((G17-F17)/F17) -> -0.0057142857 | D17: 1.75 | E17: 1.75 | F17: 1.75 | G17: 1.74 | H17: HEB | I17: 9oz bag | J17: 9 | K17: =G17/J17 -> 0.19333333 | L17: =K17*8 -> 1.5466667 | M17: =L17/16 -> 0.096666667 | N17: =M17/3 -> 0.032222222 | O17: =K17/28.3495 -> 0.0068196382
A18: HEB Bag of Lemons | F18: 4.08 | G18: 4.08 | H18: HEB | I18: 2lb bag (~10 lemons) | J18: 32 | K18: =G18/J18 -> 0.1275 | L18: =K18*8 -> 1.02 | M18: =L18/16 -> 0.06375 | N18: =M18/3 -> 0.02125 | O18: =K18/28.3495 -> 0.0044974338
A19: HEB Baby Spring Mix (10 oz) | B19: =((E19-D19)/D19) -> 0.21290323 | D19: 3.1 | E19: 3.76 | F19: 3.76 | H19: HEB | I19: 10oz box | J19: 10 | K19: =G19/J19 -> 0 | L19: =K19*8 -> 0 | M19: =L19/16 -> 0 | N19: =M19/3 -> 0 | O19: =K19/28.3495 -> 0
A20: HCF Whole Milk | B20: =((E20-D20)/D20) -> 0.058823529 | C20: =((G20-F20)/F20) -> -0.038647343 | D20: 3.91 | E20: 4.14 | F20: 4.14 | G20: 3.98 | H20: HEB | I20: 1 gal | J20: 128 | K20: =G20/J20 -> 0.03109375 | L20: =K20*8 -> 0.24875 | M20: =L20/16 -> 0.015546875 | N20: =M20/3 -> 0.0051822917 | O20: =K20/28.3495 -> 0.0010968006
A21: HCF Fat Free Milk | B21: =((E21-D21)/D21) -> 0.058823529 | C21: =((G21-F21)/F21) -> -0.038647343 | D21: 3.91 | E21: 4.14 | F21: 4.14 | G21: 3.98 | H21: HEB | I21: 1 gal | J21: 128 | K21: =G21/J21 -> 0.03109375 | L21: =K21*8 -> 0.24875 | M21: =L21/16 -> 0.015546875 | N21: =M21/3 -> 0.0051822917 | O21: =K21/28.3495 -> 0.0010968006
A22: HEB Almond Milk - Higher Harvest | B22: =((E22-D22)/D22) -> -0.15249267 | D22: 3.41 | E22: 2.89 | F22: 2.89 | H22: HEB | I22: .5 gal | J22: 64 | K22: =G22/J22 -> 0 | L22: =K22*8 -> 0 | M22: =L22/16 -> 0 | N22: =M22/3 -> 0 | O22: =K22/28.3495 -> 0
A23: HEB Original Coconut Milk | B23: =((E23-D23)/D23) -> -0.053763441 | C23: =((G23-F23)/F23) -> -0.048295455 | D23: 3.72 | E23: 3.52 | F23: 3.52 | G23: 3.35 | H23: HEB | I23: 64oz | J23: 64 | K23: =G23/J23 -> 0.05234375 | L23: =K23*8 -> 0.41875 | M23: =L23/16 -> 0.026171875 | N23: =M23/3 -> 0.0087239583 | O23: =K23/28.3495 -> 0.001846373
A24: HEB Original Oat Milk | B24: =((E24-D24)/D24) -> 0 | C24: =((G24-F24)/F24) -> -0.03960396 | D24: 4.04 | E24: 4.04 | F24: 4.04 | G24: 3.88 | H24: HEB | I24: 64oz | J24: 64 | K24: =G24/J24 -> 0.060625 | L24: =K24*8 -> 0.485 | M24: =L24/16 -> 0.0303125 | N24: =M24/3 -> 0.010104167 | O24: =K24/28.3495 -> 0.0021384857
A25: HEB Half & Half (64oz) | B25: =((E25-D25)/D25) -> 0.15811088 | C25: =((G25-F25)/F25) -> 0 | D25: 4.87 | E25: 5.64 | F25: 5.64 | G25: 5.64 | H25: HEB | I25: 64oz | J25: 64 | K25: =G25/J25 -> 0.088125 | L25: =K25*8 -> 0.705 | M25: =L25/16 -> 0.0440625 | N25: =M25/3 -> 0.0146875 | O25: =K25/28.3495 -> 0.0031085204
A26: HEB Heavy Whipping Cream (32oz) | B26: =((E26-D26)/D26) -> 0.13899614 | C26: =((G26-F26)/F26) -> -0.10338983 | D26: 5.18 | E26: 5.9 | F26: 5.9 | G26: 5.29 | H26: HEB | I26: 32oz | J26: 32 | K26: =G26/J26 -> 0.1653125 | L26: =K26*8 -> 1.3225 | M26: =L26/16 -> 0.08265625 | N26: =M26/3 -> 0.027552083 | O26: =K26/28.3495 -> 0.0058312316
A27: HEB Real Original Dairy Whip Cream (13oz) | B27: =((E27-D27)/D27) -> 0.0032258065 | C27: =((G27-F27)/F27) -> -0.038585209 | D27: 3.1 | E27: 3.11 | F27: 3.11 | G27: 2.99 | H27: HEB | I27: 13oz (37 Servings) | J27: 37 | K27: =G27/J27 -> 0.080810811 | L27: =K27*8 -> 0.64648649 | M27: =L27/16 -> 0.040405405 | N27: =M27/3 -> 0.013468468 | O27: =K27/28.3495 -> 0.0028505198
A28: HEB Original Pancake & Waffle Syrup (36 oz) | B28: =((E28-D28)/D28) -> 0.17613636 | D28: 3.52 | E28: 4.14 | F28: 4.14 | H28: HEB | I28: 36oz | J28: 36 | K28: =G28/J28 -> 0 | L28: =K28*8 -> 0 | M28: =L28/16 -> 0 | N28: =M28/3 -> 0 | O28: =K28/28.3495 -> 0
A29: HEB Sweetened Condensed Milk (14 oz) | B29: =((E29-D29)/D29) -> 0 | D29: 1.92 | E29: 1.92 | F29: 1.92 | H29: HEB | I29: 14oz | J29: 14 | K29: =G29/J29 -> 0 | L29: =K29*8 -> 0 | M29: =L29/16 -> 0 | N29: =M29/3 -> 0 | O29: =K29/28.3495 -> 0
A30: La Costena Pickled Jalapeno Naco Slices (15.5oz) | C30: =((G30-F30)/F30) -> 0 | F30: 1.88 | G30: 1.88 | H30: HEB | I30: 15.5oz | J30: 15.5 | K30: =G30/J30 -> 0.12129032 | L30: =K30*8 -> 0.97032258 | M30: =L30/16 -> 0.060645161 | N30: =M30/3 -> 0.020215054 | O30: =K30/28.3495 -> 0.0042783937
A31: Honest KidsJuice Pouches (32 pack - 6.75oz) | B31: =((E31-D31)/D31) -> 0.069892473 | C31: =((G31-F31)/F31) -> 0 | D31: 14.88 | E31: 15.92 | F31: 15.92 | G31: 15.92 | H31: Amazon | I31: 32 Pack | J31: 32 | K31: =G31/J31 -> 0.4975 | L31: =K31*8 -> 3.98 | M31: =L31/16 -> 0.24875 | N31: =M31/3 -> 0.082916667 | O31: =K31/28.3495 -> 0.01754881
A32: Amazon Fresh Hazelnut Spread (26.5oz) | B32: =((E32-D32)/D32) -> 0 | C32: =((G32-F32)/F32) -> -0.049657534 | D32: 5.84 | E32: 5.84 | F32: 5.84 | G32: 5.55 | H32: Amazon | I32: 26.5 | J32: 26.5 | K32: =G32/J32 -> 0.20943396 | L32: =K32*8 -> 1.6754717 | M32: =L32/16 -> 0.10471698 | N32: =M32/3 -> 0.03490566 | O32: =K32/28.3495 -> 0.0073875716
A33: Lipton Black Tea Bags (100 bags) | B33: =((E33-D33)/D33) -> 0.16404494 | C33: =((G33-F33)/F33) -> -0.098393574 | D33: 4.45 | E33: 5.18 | F33: 4.98 | G33: 4.49 | H33: Amazon | I33: 100 bags | J33: 100 | K33: =G33/J33 -> 0.0449 | L33: =K33*8 -> 0.3592 | M33: =L33/16 -> 0.02245 | N33: =M33/3 -> 0.0074833333 | O33: =K33/28.3495 -> 0.0015838022
A34: Taylors Organic Peppermint Herbal Tea (50 count) | B34: =((E34-D34)/D34) -> 1.8416834 | C34: =((G34-F34)/F34) -> -0.47813822 | D34: 4.99 | E34: 14.18 | F34: 14.18 | G34: 7.4 | H34: Amazon | I34: 50 teabag | J34: 50 | K34: =G34/J34 -> 0.148 | L34: =K34*8 -> 1.184 | M34: =L34/16 -> 0.074 | N34: =M34/3 -> 0.024666667 | O34: =K34/28.3495 -> 0.0052205506
A35: Taylors Lemon & Ginger Tea (20 count - 6 pack) | B35: =((E35-D35)/D35) -> -0.20311958 | C35: =((G35-F35)/F35) -> 0.043497173 | D35: 28.85 | E35: 22.99 | F35: 22.99 | G35: 23.99 | H35: Amazon | I35: 120 teabag | J35: 120 | K35: =G35/J35 -> 0.19991667 | L35: =K35*8 -> 1.5993333 | M35: =L35/16 -> 0.099958333 | N35: =M35/3 -> 0.033319444 | O35: =K35/28.3495 -> 0.0070518586
A36: Taylors Earl Gray Tea (50 count) | B36: =((E36-D36)/D36) -> -0.096870343 | C36: =((G36-F36)/F36) -> 0.2310231 | D36: 6.71 | E36: 6.06 | F36: 6.06 | G36: 7.46 | H36: Amazon | I36: 50 teabag | J36: 50 | K36: =G36/J36 -> 0.1492 | L36: =K36*8 -> 1.1936 | M36: =L36/16 -> 0.0746 | N36: =M36/3 -> 0.024866667 | O36: =K36/28.3495 -> 0.0052628794
A37: Taylors English Breakfast Tea (50 count) | B37: =((E37-D37)/D37) -> 0.089766607 | C37: =((G37-F37)/F37) -> 0.15321252 | D37: 5.57 | E37: 6.07 | F37: 6.07 | G37: 7 | H37: Amazon | I37: 50 teabag | J37: 50 | K37: =G37/J37 -> 0.14 | L37: =K37*8 -> 1.12 | M37: =L37/16 -> 0.07 | N37: =M37/3 -> 0.023333333 | O37: =K37/28.3495 -> 0.0049383587
A38: Taylors Green Tea with Jasmine (50 count) | B38: =((E38-D38)/D38) -> 0.41491841 | C38: =((G38-F38)/F38) -> 0.20098847 | D38: 4.29 | E38: 6.07 | F38: 6.07 | G38: 7.29 | H38: Amazon | I38: 50 teabag | J38: 50 | K38: =G38/J38 -> 0.1458 | L38: =K38*8 -> 1.1664 | M38: =L38/16 -> 0.0729 | N38: =M38/3 -> 0.0243 | O38: =K38/28.3495 -> 0.0051429478
A39: Gold Standard Whey Protein Powder, Vanilla Ice Cream (5lb) | B39: =((E39-D39)/D39) -> 0.10491665 | C39: =((G39-F39)/F39) -> -0.13805781 | D39: 71.39 | E39: 78.88 | F39: 78.88 | G39: 67.99 | H39: Amazon | I39: 5 lb | J39: 80 | K39: =G39/J39 -> 0.849875 | L39: =K39*8 -> 6.799 | M39: =L39/16 -> 0.4249375 | N39: =M39/3 -> 0.14164583 | O39: =K39/28.3495 -> 0.029978483
A40: Z Natural Foods Bee Pollen Granules (1lb) | B40: =((E40-D40)/D40) -> 0 | C40: =((G40-F40)/F40) -> 0.15797788 | D40: 18.99 | E40: 18.99 | F40: 18.99 | G40: 21.99 | H40: Amazon | I40: 16oz | J40: 16 | K40: =G40/J40 -> 1.374375 | L40: =K40*8 -> 10.995 | M40: =L40/16 -> 0.6871875 | N40: =M40/3 -> 0.2290625 | O40: =K40/28.3495 -> 0.048479691
...

Sheet Drink Recipe Calculator
M1: Type | N1: Packaging Cost | O1: Latte Cost with packaging | P1: Latte Menu Price | Q1: COGS | R1: Profit
M2: Small hot | N2: ='Full Inventory Cost'!K144+'Full Inventory Cost'!K150+'Full Inventory Cost'!K153 -> 0.16161 | O2: ='Full Inventory Cost'!K20*10+0.34+N2 -> 0.8125475 | P2: 5.25 | Q2: =O2/P2 -> 0.15477095 | R2: =P2-O2 -> 4.4374525
A3: Core Menu Items | M3: Medium hot | N3: ='Full Inventory Cost'!K145+'Full Inventory Cost'!K150+'Full Inventory Cost'!K153 -> 0.19081 | O3: ='Full Inventory Cost'!K20*14+0.34+N3 -> 0.9661225 | P3: 6 | Q3: =O3/P3 -> 0.16102042 | R3: =P3-O3 -> 5.0338775
M4: Large Hot | N4: ='Full Inventory Cost'!K146+'Full Inventory Cost'!K150+'Full Inventory Cost'!K153 -> 0.18861 | O4: ='Full Inventory Cost'!K20*18+0.68+N4 -> 1.4282975 | P4: 7.5 | Q4: =O4/P4 -> 0.19043967 | R4: =P4-O4 -> 6.0717025
A6: Recipe : | B6: Small Matcha Latte | D6: 16oz Iced | M6: Small Iced | N6: ='Full Inventory Cost'!K147+'Full Inventory Cost'!K151+'Full Inventory Cost'!K154+'Full Inventory Cost'!K173 -> 0.21687 | O6: ='Full Inventory Cost'!K20*10+0.34+N6 -> 0.8678075 | P6: 5.25 | Q6: =O6/P6 -> 0.16529667 | R6: =P6-O6 -> 4.3821925
A7: Serving Quantity: | B7: 1 | M7: Medium Iced | N7: ='Full Inventory Cost'!K148+'Full Inventory Cost'!K151+'Full Inventory Cost'!K154+'Full Inventory Cost'!K173 -> 0.22377 | O7: ='Full Inventory Cost'!K20*14+0.34+N7 -> 0.9990825 | P7: 6 | Q7: =O7/P7 -> 0.16651375 | R7: =P7-O7 -> 5.0009175
M8: Large Iced | N8: ='Full Inventory Cost'!K149+'Full Inventory Cost'!K151+'Full Inventory Cost'!K154+'Full Inventory Cost'!K173 -> 0.22110333 | O8: ='Full Inventory Cost'!K20*16+0.68+N8 -> 1.3986033 | P8: 7.25 | Q8: =O8/P8 -> 0.1929108 | R8: =P8-O8 -> 5.8513967
A9: Ingredients | B9: Recipe | D9: Cost per unit | F9: Cost for Recipe
A10: Panini
A11: Matcha Powder | B11: 1 | C11: teaspoon | D11: ='Full Inventory Cost'!N119 -> 0.20822917 | E11: teaspoon | F11: =B11*D11 -> 0.20822917
A12: Milk | B12: 10 | C12: oz | D12: ='Full Inventory Cost'!K20 -> 0.03109375 | E12: oz | F12: =B12*D12 -> 0.3109375
A14: Packaging
A15: 16 oz iced cup | B15: 1 | C15: unit | D15: ='Full Inventory Cost'!K147 -> 0.0972 | E15: unit | F15: =B15*D15 -> 0.0972
A16: iced lid | B16: 1 | C16: unit | D16: ='Full Inventory Cost'!K151 -> 0.05099 | E16: unit | F16: =B16*D16 -> 0.05099
A17: straw | B17: 1 | C17: unit | D17: ='Full Inventory Cost'!K154 -> 0.01909 | E17: unit | F17: =B17*D17 -> 0.01909
A18: sticker | B18: 1 | C18: unit | D18: ='Full Inventory Cost'!K173 -> 0.04959 | E18: unit | F18: =B18*D18 -> 0.04959
E20: Cost per batch | F20: =SUM(F10:F17) -> 0.68644667 | G20: 20% COGS Menu Pricing | H20: 2023 Price | I20: COGS % at current price | J20: New Price | K20: COGS with New Price
E21: Cost per unit | F21: =F20/B7 -> 0.68644667 | G21: =F21*5 -> 3.4322333 | H21: 4.75 | I21: =F21/H21 -> 0.14451509 | J21: 5.5 | K21: =F21/J21 -> 0.12480848 | L21: =J21-F21 -> 4.8135533
A24: Recipe : | B24: Large Matcha Latte | D24: 24oz Iced
A25: Serving Quantity: | B25: 1
A27: Ingredients | B27: Recipe | D27: Cost per unit | F27: Cost for Recipe
A28: Panini
A29: Matcha Powder | B29: 2 | C29: teaspoon | D29: ='Full Inventory Cost'!N119 -> 0.20822917 | E29: teaspoon | F29: =B29*D29 -> 0.41645833
A30: Milk | B30: 14 | C30: oz | D30: ='Full Inventory Cost'!K20 -> 0.03109375 | E30: oz | F30: =B30*D30 -> 0.4353125
A32: Packaging
A33: 24 oz iced cup | B33: 1 | C33: unit | D33: ='Full Inventory Cost'!K149 -> 0.10143333 | E33: unit | F33: =B33*D33 -> 0.10143333
A34: iced lid | B34: 1 | C34: unit | D34: ='Full Inventory Cost'!K151 -> 0.05099 | E34: unit | F34: =B34*D34 -> 0.05099
A35: straw | B35: 1 | C35: unit | D35: ='Full Inventory Cost'!K154 -> 0.01909 | E35: unit | F35: =B35*D35 -> 0.01909
A36: sticker | B36: 1 | C36: unit | D36: ='Full Inventory Cost'!K173 -> 0.04959 | E36: unit | F36: =B36*D36 -> 0.04959
E38: Cost per batch | F38: =SUM(F28:F35) -> 1.0232842 | G38: 20% COGS Menu Pricing | H38: 2023 Price | I38: COGS % at current price | J38: New Price | K38: COGS with New Price
E39: Cost per unit | F39: =F38/B25 -> 1.0232842 | G39: =F39*5 -> 5.1164208 | H39: 6.75 | I39: =F39/H39 -> 0.15159765 | J39: 7.5 | K39: =F39/J39 -> 0.13643789 | L39: =J39-F39 -> 6.4767158
A42: Recipe : | B42: Small Chai Latte | D42: 16oz Iced
A43: Serving Quantity: | B43: 1
A45: Ingredients | B45: Recipe | D45: Cost per unit | F45: Cost for Recipe
A46: Panini
A47: Chai | B47: 5 | C47: oz | D47: ='Full Inventory Cost'!K7 -> 0.18229167 | E47: oz | F47: =B47*D47 -> 0.91145833
A48: Milk | B48: 5 | C48: oz | D48: ='Full Inventory Cost'!K20 -> 0.03109375 | E48: oz | F48: =B48*D48 -> 0.15546875
A50: Packaging
A51: 16 oz iced cup | B51: 1 | C51: unit | D51: ='Full Inventory Cost'!K147 -> 0.0972 | E51: unit | F51: =B51*D51 -> 0.0972
A52: iced lid | B52: 1 | C52: unit | D52: ='Full Inventory Cost'!K151 -> 0.05099 | E52: unit | F52: =B52*D52 -> 0.05099
...

Sheet Food Recipe Calculator
A1: 2024 Menu Recipe Calculator
A3: Core Menu Items
A6: Recipe: | B6: Blueberry Muffins
A7: Serving Quantity | B7: 12
A9: Ingredients | B9: Recipe | D9: Cost per unit | F9: Cost for Recipe
A10: Muffin
A11: Unsalted Butter | B11: 1 | C11: cup | D11: ='Full Inventory Cost'!L110 -> 1.525 | E11: cup | F11: =B11*D11 -> 1.525
A12: White Sugar | B12: 2.5 | C12: cup | D12: ='Full Inventory Cost'!L111 -> 0.3598 | E12: cup | F12: =B12*D12 -> 0.8995
A13: Eggs | B13: 4 | C13: unit | D13: ='Full Inventory Cost'!K99 -> 0.32555556 | E13: unit | F13: =B13*D13 -> 1.3022222
A14: Vanilla Extract | B14: 2 | C14: teaspoon | D14: ='Full Inventory Cost'!N115 -> 0.1040625 | E14: teaspoon | F14: =B14*D14 -> 0.208125
A15: Flour | B15: 4 | C15: cup | D15: ='Full Inventory Cost'!L112 -> 0.1498 | E15: cup | F15: =B15*D15 -> 0.5992
A16: Iodized Salt | B16: 1 | C16: teaspoon | D16: ='Full Inventory Cost'!N98 -> 0.0041025641 | E16: teaspoon | F16: =B16*D16 -> 0.0041025641
A17: Baking Powder | B17: 4 | C17: teaspoon | D17: ='Full Inventory Cost'!N94 -> 0.042798354 | E17: teaspoon | F17: =B17*D17 -> 0.17119342
A18: Whole Milk | B18: 1 | C18: cup | D18: ='Full Inventory Cost'!L20 -> 0.24875 | E18: cup | F18: =B18*D18 -> 0.24875
A19: Frozen Blueberries | B19: 3.25 | C19: cup | D19: ='Full Inventory Cost'!L10 -> 1.198 | E19: cup | F19: =B19*D19 -> 3.8935
A21: Topping
A22: Unsalted Butter | B22: 4 | C22: tablespoon | D22: ='Full Inventory Cost'!M110 -> 0.0953125 | E22: tablespoon | F22: =B22*D22 -> 0.38125
A23: White Sugar | B23: 0.5 | C23: cup | D23: =D12 -> 0.3598 | E23: cup | F23: =B23*D23 -> 0.1799
A24: Flour | B24: 0.5 | C24: cup | D24: =D15 -> 0.1498 | E24: cup | F24: =B24*D24 -> 0.0749
A26: Packaging
A27: Muffin Baking Cup | B27: =B7 -> 12 | C27: unit | D27: ='Full Inventory Cost'!K160 -> 0.11992 | E27: unit | F27: =B27*D27 -> 1.43904
A28: Kraft Brown Bag 6x8" | B28: =B7 -> 12 | C28: unit | D28: ='Full Inventory Cost'!K161 -> 0.03485 | E28: unit | F28: =B28*D28 -> 0.4182
E30: Cost per batch | F30: =SUM(F10:F29) -> 11.344883 | G30: 20% COGS Menu Pricing | H30: Current Menu Price | I30: COGS % at current price | J30: New Price | K30: COGS with New Price
E31: Cost per unit | F31: =F30/B7 -> 0.94540693 | G31: =F31*5 -> 4.7270347 | H31: 4 | I31: =F31/H31 -> 0.23635173 | J31: 4.5 | K31: =F31/J31 -> 0.21009043 | L31: =J31-F31 -> 3.5545931
A34: Recipe : | B34: Double Chocolate Muffins
A35: Serving Quantity: | B35: 12
A37: Ingredients | B37: Recipe | D37: Cost per unit | F37: Cost for Recipe
A38: Muffin
A39: Unsalted Butter | B39: 1 | C39: cup | D39: ='Full Inventory Cost'!L110 -> 1.525 | E39: cup | F39: =B39*D39 -> 1.525
A40: White Sugar | B40: 2.5 | C40: cup | D40: ='Full Inventory Cost'!L111 -> 0.3598 | E40: cup | F40: =B40*D40 -> 0.8995
A41: Eggs | B41: 4 | C41: unit | D41: ='Full Inventory Cost'!K99 -> 0.32555556 | E41: unit | F41: =B41*D41 -> 1.3022222
A42: Vanilla Extract | B42: 2 | C42: teaspoon | D42: ='Full Inventory Cost'!M115 -> 0.3121875 | E42: teaspoon | F42: =B42*D42 -> 0.624375
A43: Flour | B43: 4 | C43: cup | D43: ='Full Inventory Cost'!L112 -> 0.1498 | E43: cup | F43: =B43*D43 -> 0.5992
A44: Iodized Salt | B44: 1 | C44: teaspoon | D44: 0.01 | E44: teaspoon | F44: =B44*D44 -> 0.01
A45: Baking Powder | B45: 4 | C45: teaspoon | D45: ='Full Inventory Cost'!N94 -> 0.042798354 | E45: teaspoon | F45: =B45*D45 -> 0.17119342
A46: Whole Milk | B46: 1 | C46: cup | D46: ='Full Inventory Cost'!L20 -> 0.24875 | E46: cup | F46: =B46*D46 -> 0.24875
A47: Chocolate Chips | B47: 2 | C47: cup | D47: ='Full Inventory Cost'!L87 -> 1.5544444 | E47: cup | F47: =B47*D47 -> 3.1088889
A48: Cocoa Powder | B48: 1 | C48: cup | D48: ='Full Inventory Cost'!L88 -> 3.78 | E48: cup | F48: =B48*D48 -> 3.78
A52: Packaging
A53: Muffin Baking Cup | B53: =B35 -> 12 | C53: unit | D53: =D27 -> 0.11992 | E53: unit | F53: =B53*D53 -> 1.43904
...
